# 异常的一些问题
> 在 Java 中，所有的异常都有一个共同的祖先java.lang包中的 Throwable类。
- **Exception（异常）**
- **Error（错误）**

## 思维导图
![Throwable](http://media.dreamcat.ink/uPic/%E5%BC%82%E5%B8%B8%E5%88%86%E7%B1%BB.png)

## Error
**是程序无法处理的错误**，表示运行应用程序中较严重问题。大多数错误与代码编写者执行的操作无关，而表示代码运行时 JVM（Java 虚拟机）出现的问题。比如：`OutOfMemoryError`

## Exception
**是程序本身可以处理的异常。** 比如：

- `RuntimeException` 异常由Java虚拟机抛出。
- `NullPointerException`（要访问的变量没有引用任何对象时，抛出该异常）
- `ArithmeticException`（算术运算异常，一个整数除以0时，抛出该异常）
- `ArrayIndexOutOfBoundsException` （下标越界异常）。

## 处理

- `try` 块： 用于捕获异常。其后可接零个或多个`catch`块，如果没有`catch`块，则必须跟一个`finally`块。
- `catch` 块： 用于处理`try`捕获到的异常。
- `finally` 块： 无论是否捕获或处理异常，`finally`块里的语句都会被执行。当在`try`块或`catch`块中遇到`return`语句时，`finally`语句块将在方法返回之前被执行。

> 注意：当try语句和finally语句中都有return语句时，在方法返回之前，finally语句的内容将被执行，并且finally语句的返回值将会**覆盖原始的返回值**。如下：

```java
  public static int f(int value) {
      try {
          return value * value;
      } finally {
          if (value == 2) {
              return 0;
          }
      }
  }
```

## throw和throws
> 抛出异常

throw的例子：

```java
public class Test1 {
    public static void main(String[] args) {
        if(true) {
            throw new NumberFormatException(); // 抛出一个异常
        } else {
            ...
        }
    }
}
```

throws是方法可能抛出异常的声明。(用在声明方法时，表示该方法可能要抛出异常)，throws例子：

```java
public class Test2 {
    public void fun() throws NumberFormatException {
        if(true) {
            throw new NumberFormatException();
        }
    }
}
```